Workbook

Sheet DASHBOARD
A1: MONITORING BANTUAN TEKNIS - ASISTENSI TEKNIS
B3: Total Laporan | D3: Selesai | F3: Masih Proses | H3: % Selesai
B4: =COUNTA('Data R1'!$C$4:$C$1001)+COUNTA('Data R2'!$C$4:$C$1001)+COUNTA('Data R3'!$C$4:$C$1001)+COUNTA('Data R4'!$C$4:$C$1001)+COUNTA('Data R5'!$C$4:$C$1001)+COUNTA('Data R6'!$C$4:$C$1001)+COUNTA('Data R7'!$C$4:$C$1001)+COUNTA('Data R4P'!$C$4:$C$1001)+COUNTA('Data SW'!$C$4:$C$1001) | D4: =COUNTIF('Data R1'!$AC$4:$AC$1001,"SELESAI")+COUNTIF('Data R2'!$AC$4:$AC$1001,"SELESAI")+COUNTIF('Data R3'!$AC$4:$AC$1001,"SELESAI")+COUNTIF('Data R4'!$AC$4:$AC$1001,"SELESAI")+COUNTIF('Data R5'!$AC$4:$AC$1001,"SELESAI")+COUNTIF('Data R6'!$AC$4:$AC$1001,"SELESAI")+COUNTIF('Data R7'!$AC$4:$AC$1001,"SELESAI")+COUNTIF('Data R4P'!$AC$4:$AC$1001,"SELESAI")+COUNTIF('Data SW'!$AC$4:$AC$1001,"SELESAI") | F4: =COUNTIF('Data R1'!$AC$4:$AC$1001,"PROSES")+COUNTIF('Data R2'!$AC$4:$AC$1001,"PROSES")+COUNTIF('Data R3'!$AC$4:$AC$1001,"PROSES")+COUNTIF('Data R4'!$AC$4:$AC$1001,"PROSES")+COUNTIF('Data R5'!$AC$4:$AC$1001,"PROSES")+COUNTIF('Data R6'!$AC$4:$AC$1001,"PROSES")+COUNTIF('Data R7'!$AC$4:$AC$1001,"PROSES")+COUNTIF('Data R4P'!$AC$4:$AC$1001,"PROSES")+COUNTIF('Data SW'!$AC$4:$AC$1001,"PROSES") | H4: =IF(B4=0,0,ROUND(D4/B4*100,1))
A6: RINGKASAN STATUS PER REGIONAL
A7: Regional | B7: Total | C7: Selesai | D7: Proses | E7: % Selesai
A8: Regional 1 | B8: =COUNTA('Data R1'!$C$4:$C$1001) | C8: =COUNTIF('Data R1'!$AC$4:$AC$1001,"SELESAI") | D8: =COUNTIF('Data R1'!$AC$4:$AC$1001,"PROSES") | E8: =IF(B8=0,0,ROUND(C8/B8*100,1))
A9: Regional 2 | B9: =COUNTA('Data R2'!$C$4:$C$1001) | C9: =COUNTIF('Data R2'!$AC$4:$AC$1001,"SELESAI") | D9: =COUNTIF('Data R2'!$AC$4:$AC$1001,"PROSES") | E9: =IF(B9=0,0,ROUND(C9/B9*100,1))
A10: Regional 3 | B10: =COUNTA('Data R3'!$C$4:$C$1001) | C10: =COUNTIF('Data R3'!$AC$4:$AC$1001,"SELESAI") | D10: =COUNTIF('Data R3'!$AC$4:$AC$1001,"PROSES") | E10: =IF(B10=0,0,ROUND(C10/B10*100,1))
A11: Regional 4 | B11: =COUNTA('Data R4'!$C$4:$C$1001) | C11: =COUNTIF('Data R4'!$AC$4:$AC$1001,"SELESAI") | D11: =COUNTIF('Data R4'!$AC$4:$AC$1001,"PROSES") | E11: =IF(B11=0,0,ROUND(C11/B11*100,1))
A12: Regional 5 | B12: =COUNTA('Data R5'!$C$4:$C$1001) | C12: =COUNTIF('Data R5'!$AC$4:$AC$1001,"SELESAI") | D12: =COUNTIF('Data R5'!$AC$4:$AC$1001,"PROSES") | E12: =IF(B12=0,0,ROUND(C12/B12*100,1))
A13: Regional 6 | B13: =COUNTA('Data R6'!$C$4:$C$1001) | C13: =COUNTIF('Data R6'!$AC$4:$AC$1001,"SELESAI") | D13: =COUNTIF('Data R6'!$AC$4:$AC$1001,"PROSES") | E13: =IF(B13=0,0,ROUND(C13/B13*100,1))
A14: Regional 7 | B14: =COUNTA('Data R7'!$C$4:$C$1001) | C14: =COUNTIF('Data R7'!$AC$4:$AC$1001,"SELESAI") | D14: =COUNTIF('Data R7'!$AC$4:$AC$1001,"PROSES") | E14: =IF(B14=0,0,ROUND(C14/B14*100,1))
A15: Regional 4 Palmco | B15: =COUNTA('Data R4P'!$C$4:$C$1001) | C15: =COUNTIF('Data R4P'!$AC$4:$AC$1001,"SELESAI") | D15: =COUNTIF('Data R4P'!$AC$4:$AC$1001,"PROSES") | E15: =IF(B15=0,0,ROUND(C15/B15*100,1))
A16: PT Swasta / PPKS | B16: =COUNTA('Data SW'!$C$4:$C$1001) | C16: =COUNTIF('Data SW'!$AC$4:$AC$1001,"SELESAI") | D16: =COUNTIF('Data SW'!$AC$4:$AC$1001,"PROSES") | E16: =IF(B16=0,0,ROUND(C16/B16*100,1))
A17: TOTAL | B17: =SUM(B8:B16) | C17: =SUM(C8:C16) | D17: =SUM(D8:D16) | E17: =IF(B17=0,0,ROUND(C17/B17*100,1))
A19: MATRIK SELESAI per Regional x Tahun
A20: Regional | B20: 2024 | C20: 2025 | D20: 2026 | E20: TOTAL
A21: Regional 1 | B21: =COUNTIFS('Data R1'!$AD$4:$AD$1001,2024,'Data R1'!$AC$4:$AC$1001,"SELESAI") | C21: =COUNTIFS('Data R1'!$AD$4:$AD$1001,2025,'Data R1'!$AC$4:$AC$1001,"SELESAI") | D21: =COUNTIFS('Data R1'!$AD$4:$AD$1001,2026,'Data R1'!$AC$4:$AC$1001,"SELESAI") | E21: =SUM(B21:D21)
A22: Regional 2 | B22: =COUNTIFS('Data R2'!$AD$4:$AD$1001,2024,'Data R2'!$AC$4:$AC$1001,"SELESAI") | C22: =COUNTIFS('Data R2'!$AD$4:$AD$1001,2025,'Data R2'!$AC$4:$AC$1001,"SELESAI") | D22: =COUNTIFS('Data R2'!$AD$4:$AD$1001,2026,'Data R2'!$AC$4:$AC$1001,"SELESAI") | E22: =SUM(B22:D22)
A23: Regional 3 | B23: =COUNTIFS('Data R3'!$AD$4:$AD$1001,2024,'Data R3'!$AC$4:$AC$1001,"SELESAI") | C23: =COUNTIFS('Data R3'!$AD$4:$AD$1001,2025,'Data R3'!$AC$4:$AC$1001,"SELESAI") | D23: =COUNTIFS('Data R3'!$AD$4:$AD$1001,2026,'Data R3'!$AC$4:$AC$1001,"SELESAI") | E23: =SUM(B23:D23)
A24: Regional 4 | B24: =COUNTIFS('Data R4'!$AD$4:$AD$1001,2024,'Data R4'!$AC$4:$AC$1001,"SELESAI") | C24: =COUNTIFS('Data R4'!$AD$4:$AD$1001,2025,'Data R4'!$AC$4:$AC$1001,"SELESAI") | D24: =COUNTIFS('Data R4'!$AD$4:$AD$1001,2026,'Data R4'!$AC$4:$AC$1001,"SELESAI") | E24: =SUM(B24:D24)
A25: Regional 5 | B25: =COUNTIFS('Data R5'!$AD$4:$AD$1001,2024,'Data R5'!$AC$4:$AC$1001,"SELESAI") | C25: =COUNTIFS('Data R5'!$AD$4:$AD$1001,2025,'Data R5'!$AC$4:$AC$1001,"SELESAI") | D25: =COUNTIFS('Data R5'!$AD$4:$AD$1001,2026,'Data R5'!$AC$4:$AC$1001,"SELESAI") | E25: =SUM(B25:D25)
A26: Regional 6 | B26: =COUNTIFS('Data R6'!$AD$4:$AD$1001,2024,'Data R6'!$AC$4:$AC$1001,"SELESAI") | C26: =COUNTIFS('Data R6'!$AD$4:$AD$1001,2025,'Data R6'!$AC$4:$AC$1001,"SELESAI") | D26: =COUNTIFS('Data R6'!$AD$4:$AD$1001,2026,'Data R6'!$AC$4:$AC$1001,"SELESAI") | E26: =SUM(B26:D26)
A27: Regional 7 | B27: =COUNTIFS('Data R7'!$AD$4:$AD$1001,2024,'Data R7'!$AC$4:$AC$1001,"SELESAI") | C27: =COUNTIFS('Data R7'!$AD$4:$AD$1001,2025,'Data R7'!$AC$4:$AC$1001,"SELESAI") | D27: =COUNTIFS('Data R7'!$AD$4:$AD$1001,2026,'Data R7'!$AC$4:$AC$1001,"SELESAI") | E27: =SUM(B27:D27)
A28: Regional 4 Palmco | B28: =COUNTIFS('Data R4P'!$AD$4:$AD$1001,2024,'Data R4P'!$AC$4:$AC$1001,"SELESAI") | C28: =COUNTIFS('Data R4P'!$AD$4:$AD$1001,2025,'Data R4P'!$AC$4:$AC$1001,"SELESAI") | D28: =COUNTIFS('Data R4P'!$AD$4:$AD$1001,2026,'Data R4P'!$AC$4:$AC$1001,"SELESAI") | E28: =SUM(B28:D28)
A29: PT Swasta / PPKS | B29: =COUNTIFS('Data SW'!$AD$4:$AD$1001,2024,'Data SW'!$AC$4:$AC$1001,"SELESAI") | C29: =COUNTIFS('Data SW'!$AD$4:$AD$1001,2025,'Data SW'!$AC$4:$AC$1001,"SELESAI") | D29: =COUNTIFS('Data SW'!$AD$4:$AD$1001,2026,'Data SW'!$AC$4:$AC$1001,"SELESAI") | E29: =SUM(B29:D29)
A30: TOTAL | B30: =SUM(B21:B29) | C30: =SUM(C21:C29) | D30: =SUM(D21:D29) | E30: =SUM(E21:E29)
A32: MATRIK PROSES per Regional x Tahun
A33: Regional | B33: 2024 | C33: 2025 | D33: 2026 | E33: TOTAL
A34: Regional 1 | B34: =COUNTIFS('Data R1'!$AD$4:$AD$1001,2024,'Data R1'!$AC$4:$AC$1001,"PROSES") | C34: =COUNTIFS('Data R1'!$AD$4:$AD$1001,2025,'Data R1'!$AC$4:$AC$1001,"PROSES") | D34: =COUNTIFS('Data R1'!$AD$4:$AD$1001,2026,'Data R1'!$AC$4:$AC$1001,"PROSES") | E34: =SUM(B34:D34)
A35: Regional 2 | B35: =COUNTIFS('Data R2'!$AD$4:$AD$1001,2024,'Data R2'!$AC$4:$AC$1001,"PROSES") | C35: =COUNTIFS('Data R2'!$AD$4:$AD$1001,2025,'Data R2'!$AC$4:$AC$1001,"PROSES") | D35: =COUNTIFS('Data R2'!$AD$4:$AD$1001,2026,'Data R2'!$AC$4:$AC$1001,"PROSES") | E35: =SUM(B35:D35)
A36: Regional 3 | B36: =COUNTIFS('Data R3'!$AD$4:$AD$1001,2024,'Data R3'!$AC$4:$AC$1001,"PROSES") | C36: =COUNTIFS('Data R3'!$AD$4:$AD$1001,2025,'Data R3'!$AC$4:$AC$1001,"PROSES") | D36: =COUNTIFS('Data R3'!$AD$4:$AD$1001,2026,'Data R3'!$AC$4:$AC$1001,"PROSES") | E36: =SUM(B36:D36)
A37: Regional 4 | B37: =COUNTIFS('Data R4'!$AD$4:$AD$1001,2024,'Data R4'!$AC$4:$AC$1001,"PROSES") | C37: =COUNTIFS('Data R4'!$AD$4:$AD$1001,2025,'Data R4'!$AC$4:$AC$1001,"PROSES") | D37: =COUNTIFS('Data R4'!$AD$4:$AD$1001,2026,'Data R4'!$AC$4:$AC$1001,"PROSES") | E37: =SUM(B37:D37)
A38: Regional 5 | B38: =COUNTIFS('Data R5'!$AD$4:$AD$1001,2024,'Data R5'!$AC$4:$AC$1001,"PROSES") | C38: =COUNTIFS('Data R5'!$AD$4:$AD$1001,2025,'Data R5'!$AC$4:$AC$1001,"PROSES") | D38: =COUNTIFS('Data R5'!$AD$4:$AD$1001,2026,'Data R5'!$AC$4:$AC$1001,"PROSES") | E38: =SUM(B38:D38)
A39: Regional 6 | B39: =COUNTIFS('Data R6'!$AD$4:$AD$1001,2024,'Data R6'!$AC$4:$AC$1001,"PROSES") | C39: =COUNTIFS('Data R6'!$AD$4:$AD$1001,2025,'Data R6'!$AC$4:$AC$1001,"PROSES") | D39: =COUNTIFS('Data R6'!$AD$4:$AD$1001,2026,'Data R6'!$AC$4:$AC$1001,"PROSES") | E39: =SUM(B39:D39)
A40: Regional 7 | B40: =COUNTIFS('Data R7'!$AD$4:$AD$1001,2024,'Data R7'!$AC$4:$AC$1001,"PROSES") | C40: =COUNTIFS('Data R7'!$AD$4:$AD$1001,2025,'Data R7'!$AC$4:$AC$1001,"PROSES") | D40: =COUNTIFS('Data R7'!$AD$4:$AD$1001,2026,'Data R7'!$AC$4:$AC$1001,"PROSES") | E40: =SUM(B40:D40)
A41: Regional 4 Palmco | B41: =COUNTIFS('Data R4P'!$AD$4:$AD$1001,2024,'Data R4P'!$AC$4:$AC$1001,"PROSES") | C41: =COUNTIFS('Data R4P'!$AD$4:$AD$1001,2025,'Data R4P'!$AC$4:$AC$1001,"PROSES") | D41: =COUNTIFS('Data R4P'!$AD$4:$AD$1001,2026,'Data R4P'!$AC$4:$AC$1001,"PROSES") | E41: =SUM(B41:D41)
A42: PT Swasta / PPKS | B42: =COUNTIFS('Data SW'!$AD$4:$AD$1001,2024,'Data SW'!$AC$4:$AC$1001,"PROSES") | C42: =COUNTIFS('Data SW'!$AD$4:$AD$1001,2025,'Data SW'!$AC$4:$AC$1001,"PROSES") | D42: =COUNTIFS('Data SW'!$AD$4:$AD$1001,2026,'Data SW'!$AC$4:$AC$1001,"PROSES") | E42: =SUM(B42:D42)
A43: TOTAL | B43: =SUM(B34:B42) | C43: =SUM(C34:C42) | D43: =SUM(D34:D42) | E43: =SUM(E34:E42)
A45: STATUS PER KATEGORI KEGIATAN
...

Sheet DATA DASH
A1: Regional | B1: Perusahaan | C1: Kebun | D1: Petugas | E1: TanggalKunjungan | F1: Kegiatan | G1: Tahun | H1: Status | I1: JumlahKorektor | J1: AdaKeluar | K1: KategoriKegiatan | L1: KorektorPerKebun | M1: SumberBeban
A2: Regional 1 | B2: =IF('Data R1'!C4="","",'Data R1'!B4) | C2: =IF('Data R1'!C4="","",'Data R1'!C4) | D2: =IF('Data R1'!C4="","",'Data R1'!D4) | E2: =IF('Data R1'!C4="","",'Data R1'!E4) | F2: =IF('Data R1'!C4="","",'Data R1'!F4) | G2: =IF('Data R1'!C4="","",'Data R1'!AD4) | H2: =IF('Data R1'!C4="","",'Data R1'!AC4) | I2: =IF('Data R1'!C4="","",COUNTIF('Data R1'!J4,">0")+COUNTIF('Data R1'!L4,">0")+COUNTIF('Data R1'!N4,">0")+COUNTIF('Data R1'!P4,">0")+COUNTIF('Data R1'!R4,">0")+COUNTIF('Data R1'!T4,">0")+COUNTIF('Data R1'!V4,">0")+COUNTIF('Data R1'!X4,">0")) | J2: =IF('Data R1'!C4="","",IF((COUNTIF('Data R1'!K4,">0")+COUNTIF('Data R1'!M4,">0")+COUNTIF('Data R1'!O4,">0")+COUNTIF('Data R1'!Q4,">0")+COUNTIF('Data R1'!S4,">0")+COUNTIF('Data R1'!U4,">0")+COUNTIF('Data R1'!W4,">0")+COUNTIF('Data R1'!Y4,">0"))>0,1,0)) | K2: Produksi / Kultur Teknis | M2: Data R
A3: Regional 1 | B3: =IF('Data R1'!C5="","",'Data R1'!B5) | C3: =IF('Data R1'!C5="","",'Data R1'!C5) | D3: =IF('Data R1'!C5="","",'Data R1'!D5) | E3: =IF('Data R1'!C5="","",'Data R1'!E5) | F3: =IF('Data R1'!C5="","",'Data R1'!F5) | G3: =IF('Data R1'!C5="","",'Data R1'!AD5) | H3: =IF('Data R1'!C5="","",'Data R1'!AC5) | I3: =IF('Data R1'!C5="","",COUNTIF('Data R1'!J5,">0")+COUNTIF('Data R1'!L5,">0")+COUNTIF('Data R1'!N5,">0")+COUNTIF('Data R1'!P5,">0")+COUNTIF('Data R1'!R5,">0")+COUNTIF('Data R1'!T5,">0")+COUNTIF('Data R1'!V5,">0")+COUNTIF('Data R1'!X5,">0")) | J3: =IF('Data R1'!C5="","",IF((COUNTIF('Data R1'!K5,">0")+COUNTIF('Data R1'!M5,">0")+COUNTIF('Data R1'!O5,">0")+COUNTIF('Data R1'!Q5,">0")+COUNTIF('Data R1'!S5,">0")+COUNTIF('Data R1'!U5,">0")+COUNTIF('Data R1'!W5,">0")+COUNTIF('Data R1'!Y5,">0"))>0,1,0)) | K3: Tanam Ulang / Program TU | L3: Pak Edi Sigit Sutarta; Pak Iput Pradiko; Buk Nuzul Hijri | M3: Data R
A4: Regional 1 | B4: =IF('Data R1'!C6="","",'Data R1'!B6) | C4: =IF('Data R1'!C6="","",'Data R1'!C6) | D4: =IF('Data R1'!C6="","",'Data R1'!D6) | E4: =IF('Data R1'!C6="","",'Data R1'!E6) | F4: =IF('Data R1'!C6="","",'Data R1'!F6) | G4: =IF('Data R1'!C6="","",'Data R1'!AD6) | H4: =IF('Data R1'!C6="","",'Data R1'!AC6) | I4: =IF('Data R1'!C6="","",COUNTIF('Data R1'!J6,">0")+COUNTIF('Data R1'!L6,">0")+COUNTIF('Data R1'!N6,">0")+COUNTIF('Data R1'!P6,">0")+COUNTIF('Data R1'!R6,">0")+COUNTIF('Data R1'!T6,">0")+COUNTIF('Data R1'!V6,">0")+COUNTIF('Data R1'!X6,">0")) | J4: =IF('Data R1'!C6="","",IF((COUNTIF('Data R1'!K6,">0")+COUNTIF('Data R1'!M6,">0")+COUNTIF('Data R1'!O6,">0")+COUNTIF('Data R1'!Q6,">0")+COUNTIF('Data R1'!S6,">0")+COUNTIF('Data R1'!U6,">0")+COUNTIF('Data R1'!W6,">0")+COUNTIF('Data R1'!Y6,">0"))>0,1,0)) | L4: Pak Edi Sigit Sutarta; Pak Iput Pradiko; Buk Nuzul Hijri | M4: Data R
A5: Regional 1 | B5: =IF('Data R1'!C7="","",'Data R1'!B7) | C5: =IF('Data R1'!C7="","",'Data R1'!C7) | D5: =IF('Data R1'!C7="","",'Data R1'!D7) | E5: =IF('Data R1'!C7="","",'Data R1'!E7) | F5: =IF('Data R1'!C7="","",'Data R1'!F7) | G5: =IF('Data R1'!C7="","",'Data R1'!AD7) | H5: =IF('Data R1'!C7="","",'Data R1'!AC7) | I5: =IF('Data R1'!C7="","",COUNTIF('Data R1'!J7,">0")+COUNTIF('Data R1'!L7,">0")+COUNTIF('Data R1'!N7,">0")+COUNTIF('Data R1'!P7,">0")+COUNTIF('Data R1'!R7,">0")+COUNTIF('Data R1'!T7,">0")+COUNTIF('Data R1'!V7,">0")+COUNTIF('Data R1'!X7,">0")) | J5: =IF('Data R1'!C7="","",IF((COUNTIF('Data R1'!K7,">0")+COUNTIF('Data R1'!M7,">0")+COUNTIF('Data R1'!O7,">0")+COUNTIF('Data R1'!Q7,">0")+COUNTIF('Data R1'!S7,">0")+COUNTIF('Data R1'!U7,">0")+COUNTIF('Data R1'!W7,">0")+COUNTIF('Data R1'!Y7,">0"))>0,1,0)) | K5: Tanam Ulang / Program TU | L5: Pak Edi Sigit Sutarta; Pak Iput Pradiko; Buk Nuzul Hijri; Pak Eko | M5: Data R
A6: Regional 1 | B6: =IF('Data R1'!C8="","",'Data R1'!B8) | C6: =IF('Data R1'!C8="","",'Data R1'!C8) | D6: =IF('Data R1'!C8="","",'Data R1'!D8) | E6: =IF('Data R1'!C8="","",'Data R1'!E8) | F6: =IF('Data R1'!C8="","",'Data R1'!F8) | G6: =IF('Data R1'!C8="","",'Data R1'!AD8) | H6: =IF('Data R1'!C8="","",'Data R1'!AC8) | I6: =IF('Data R1'!C8="","",COUNTIF('Data R1'!J8,">0")+COUNTIF('Data R1'!L8,">0")+COUNTIF('Data R1'!N8,">0")+COUNTIF('Data R1'!P8,">0")+COUNTIF('Data R1'!R8,">0")+COUNTIF('Data R1'!T8,">0")+COUNTIF('Data R1'!V8,">0")+COUNTIF('Data R1'!X8,">0")) | J6: =IF('Data R1'!C8="","",IF((COUNTIF('Data R1'!K8,">0")+COUNTIF('Data R1'!M8,">0")+COUNTIF('Data R1'!O8,">0")+COUNTIF('Data R1'!Q8,">0")+COUNTIF('Data R1'!S8,">0")+COUNTIF('Data R1'!U8,">0")+COUNTIF('Data R1'!W8,">0")+COUNTIF('Data R1'!Y8,">0"))>0,1,0)) | L6: Pak Edi Sigit Sutarta; Pak Iput Pradiko; Buk Nuzul Hijri; Pak Eko | M6: Data R
A7: Regional 1 | B7: =IF('Data R1'!C9="","",'Data R1'!B9) | C7: =IF('Data R1'!C9="","",'Data R1'!C9) | D7: =IF('Data R1'!C9="","",'Data R1'!D9) | E7: =IF('Data R1'!C9="","",'Data R1'!E9) | F7: =IF('Data R1'!C9="","",'Data R1'!F9) | G7: =IF('Data R1'!C9="","",'Data R1'!AD9) | H7: =IF('Data R1'!C9="","",'Data R1'!AC9) | I7: =IF('Data R1'!C9="","",COUNTIF('Data R1'!J9,">0")+COUNTIF('Data R1'!L9,">0")+COUNTIF('Data R1'!N9,">0")+COUNTIF('Data R1'!P9,">0")+COUNTIF('Data R1'!R9,">0")+COUNTIF('Data R1'!T9,">0")+COUNTIF('Data R1'!V9,">0")+COUNTIF('Data R1'!X9,">0")) | J7: =IF('Data R1'!C9="","",IF((COUNTIF('Data R1'!K9,">0")+COUNTIF('Data R1'!M9,">0")+COUNTIF('Data R1'!O9,">0")+COUNTIF('Data R1'!Q9,">0")+COUNTIF('Data R1'!S9,">0")+COUNTIF('Data R1'!U9,">0")+COUNTIF('Data R1'!W9,">0")+COUNTIF('Data R1'!Y9,">0"))>0,1,0)) | L7: Pak Edi Sigit Sutarta; Pak Iput Pradiko; Buk Nuzul Hijri; Pak Eko | M7: Data R
A8: Regional 1 | B8: =IF('Data R1'!C10="","",'Data R1'!B10) | C8: =IF('Data R1'!C10="","",'Data R1'!C10) | D8: =IF('Data R1'!C10="","",'Data R1'!D10) | E8: =IF('Data R1'!C10="","",'Data R1'!E10) | F8: =IF('Data R1'!C10="","",'Data R1'!F10) | G8: =IF('Data R1'!C10="","",'Data R1'!AD10) | H8: =IF('Data R1'!C10="","",'Data R1'!AC10) | I8: =IF('Data R1'!C10="","",COUNTIF('Data R1'!J10,">0")+COUNTIF('Data R1'!L10,">0")+COUNTIF('Data R1'!N10,">0")+COUNTIF('Data R1'!P10,">0")+COUNTIF('Data R1'!R10,">0")+COUNTIF('Data R1'!T10,">0")+COUNTIF('Data R1'!V10,">0")+COUNTIF('Data R1'!X10,">0")) | J8: =IF('Data R1'!C10="","",IF((COUNTIF('Data R1'!K10,">0")+COUNTIF('Data R1'!M10,">0")+COUNTIF('Data R1'!O10,">0")+COUNTIF('Data R1'!Q10,">0")+COUNTIF('Data R1'!S10,">0")+COUNTIF('Data R1'!U10,">0")+COUNTIF('Data R1'!W10,">0")+COUNTIF('Data R1'!Y10,">0"))>0,1,0)) | K8: Produksi / Kultur Teknis | L8: Pak Edi Sigit Sutarta; Pak Iput Pradiko; Buk Nuzul Hijri | M8: Data R
A9: Regional 1 | B9: =IF('Data R1'!C11="","",'Data R1'!B11) | C9: =IF('Data R1'!C11="","",'Data R1'!C11) | D9: =IF('Data R1'!C11="","",'Data R1'!D11) | E9: =IF('Data R1'!C11="","",'Data R1'!E11) | F9: =IF('Data R1'!C11="","",'Data R1'!F11) | G9: =IF('Data R1'!C11="","",'Data R1'!AD11) | H9: =IF('Data R1'!C11="","",'Data R1'!AC11) | I9: =IF('Data R1'!C11="","",COUNTIF('Data R1'!J11,">0")+COUNTIF('Data R1'!L11,">0")+COUNTIF('Data R1'!N11,">0")+COUNTIF('Data R1'!P11,">0")+COUNTIF('Data R1'!R11,">0")+COUNTIF('Data R1'!T11,">0")+COUNTIF('Data R1'!V11,">0")+COUNTIF('Data R1'!X11,">0")) | J9: =IF('Data R1'!C11="","",IF((COUNTIF('Data R1'!K11,">0")+COUNTIF('Data R1'!M11,">0")+COUNTIF('Data R1'!O11,">0")+COUNTIF('Data R1'!Q11,">0")+COUNTIF('Data R1'!S11,">0")+COUNTIF('Data R1'!U11,">0")+COUNTIF('Data R1'!W11,">0")+COUNTIF('Data R1'!Y11,">0"))>0,1,0)) | L9: Pak Edi Sigit Sutarta; Pak Iput Pradiko; Buk Nuzul Hijri | M9: Data R
A10: Regional 1 | B10: =IF('Data R1'!C12="","",'Data R1'!B12) | C10: =IF('Data R1'!C12="","",'Data R1'!C12) | D10: =IF('Data R1'!C12="","",'Data R1'!D12) | E10: =IF('Data R1'!C12="","",'Data R1'!E12) | F10: =IF('Data R1'!C12="","",'Data R1'!F12) | G10: =IF('Data R1'!C12="","",'Data R1'!AD12) | H10: =IF('Data R1'!C12="","",'Data R1'!AC12) | I10: =IF('Data R1'!C12="","",COUNTIF('Data R1'!J12,">0")+COUNTIF('Data R1'!L12,">0")+COUNTIF('Data R1'!N12,">0")+COUNTIF('Data R1'!P12,">0")+COUNTIF('Data R1'!R12,">0")+COUNTIF('Data R1'!T12,">0")+COUNTIF('Data R1'!V12,">0")+COUNTIF('Data R1'!X12,">0")) | J10: =IF('Data R1'!C12="","",IF((COUNTIF('Data R1'!K12,">0")+COUNTIF('Data R1'!M12,">0")+COUNTIF('Data R1'!O12,">0")+COUNTIF('Data R1'!Q12,">0")+COUNTIF('Data R1'!S12,">0")+COUNTIF('Data R1'!U12,">0")+COUNTIF('Data R1'!W12,">0")+COUNTIF('Data R1'!Y12,">0"))>0,1,0)) | K10: Tanam Ulang / Program TU | L10: Pak Edi Sigit Sutarta; Pak Iput Pradiko | M10: Data R
A11: Regional 1 | B11: =IF('Data R1'!C13="","",'Data R1'!B13) | C11: =IF('Data R1'!C13="","",'Data R1'!C13) | D11: =IF('Data R1'!C13="","",'Data R1'!D13) | E11: =IF('Data R1'!C13="","",'Data R1'!E13) | F11: =IF('Data R1'!C13="","",'Data R1'!F13) | G11: =IF('Data R1'!C13="","",'Data R1'!AD13) | H11: =IF('Data R1'!C13="","",'Data R1'!AC13) | I11: =IF('Data R1'!C13="","",COUNTIF('Data R1'!J13,">0")+COUNTIF('Data R1'!L13,">0")+COUNTIF('Data R1'!N13,">0")+COUNTIF('Data R1'!P13,">0")+COUNTIF('Data R1'!R13,">0")+COUNTIF('Data R1'!T13,">0")+COUNTIF('Data R1'!V13,">0")+COUNTIF('Data R1'!X13,">0")) | J11: =IF('Data R1'!C13="","",IF((COUNTIF('Data R1'!K13,">0")+COUNTIF('Data R1'!M13,">0")+COUNTIF('Data R1'!O13,">0")+COUNTIF('Data R1'!Q13,">0")+COUNTIF('Data R1'!S13,">0")+COUNTIF('Data R1'!U13,">0")+COUNTIF('Data R1'!W13,">0")+COUNTIF('Data R1'!Y13,">0"))>0,1,0)) | L11: Pak Edi Sigit Sutarta; Pak Iput Pradiko | M11: Data R
A12: Regional 1 | B12: =IF('Data R1'!C14="","",'Data R1'!B14) | C12: =IF('Data R1'!C14="","",'Data R1'!C14) | D12: =IF('Data R1'!C14="","",'Data R1'!D14) | E12: =IF('Data R1'!C14="","",'Data R1'!E14) | F12: =IF('Data R1'!C14="","",'Data R1'!F14) | G12: =IF('Data R1'!C14="","",'Data R1'!AD14) | H12: =IF('Data R1'!C14="","",'Data R1'!AC14) | I12: =IF('Data R1'!C14="","",COUNTIF('Data R1'!J14,">0")+COUNTIF('Data R1'!L14,">0")+COUNTIF('Data R1'!N14,">0")+COUNTIF('Data R1'!P14,">0")+COUNTIF('Data R1'!R14,">0")+COUNTIF('Data R1'!T14,">0")+COUNTIF('Data R1'!V14,">0")+COUNTIF('Data R1'!X14,">0")) | J12: =IF('Data R1'!C14="","",IF((COUNTIF('Data R1'!K14,">0")+COUNTIF('Data R1'!M14,">0")+COUNTIF('Data R1'!O14,">0")+COUNTIF('Data R1'!Q14,">0")+COUNTIF('Data R1'!S14,">0")+COUNTIF('Data R1'!U14,">0")+COUNTIF('Data R1'!W14,">0")+COUNTIF('Data R1'!Y14,">0"))>0,1,0)) | L12: Pak Edi Sigit Sutarta; Pak Iput Pradiko | M12: Data R
A13: Regional 1 | B13: =IF('Data R1'!C15="","",'Data R1'!B15) | C13: =IF('Data R1'!C15="","",'Data R1'!C15) | D13: =IF('Data R1'!C15="","",'Data R1'!D15) | E13: =IF('Data R1'!C15="","",'Data R1'!E15) | F13: =IF('Data R1'!C15="","",'Data R1'!F15) | G13: =IF('Data R1'!C15="","",'Data R1'!AD15) | H13: =IF('Data R1'!C15="","",'Data R1'!AC15) | I13: =IF('Data R1'!C15="","",COUNTIF('Data R1'!J15,">0")+COUNTIF('Data R1'!L15,">0")+COUNTIF('Data R1'!N15,">0")+COUNTIF('Data R1'!P15,">0")+COUNTIF('Data R1'!R15,">0")+COUNTIF('Data R1'!T15,">0")+COUNTIF('Data R1'!V15,">0")+COUNTIF('Data R1'!X15,">0")) | J13: =IF('Data R1'!C15="","",IF((COUNTIF('Data R1'!K15,">0")+COUNTIF('Data R1'!M15,">0")+COUNTIF('Data R1'!O15,">0")+COUNTIF('Data R1'!Q15,">0")+COUNTIF('Data R1'!S15,">0")+COUNTIF('Data R1'!U15,">0")+COUNTIF('Data R1'!W15,">0")+COUNTIF('Data R1'!Y15,">0"))>0,1,0)) | L13: Pak Edi Sigit Sutarta; Pak Iput Pradiko | M13: Data R
A14: Regional 1 | B14: =IF('Data R1'!C16="","",'Data R1'!B16) | C14: =IF('Data R1'!C16="","",'Data R1'!C16) | D14: =IF('Data R1'!C16="","",'Data R1'!D16) | E14: =IF('Data R1'!C16="","",'Data R1'!E16) | F14: =IF('Data R1'!C16="","",'Data R1'!F16) | G14: =IF('Data R1'!C16="","",'Data R1'!AD16) | H14: =IF('Data R1'!C16="","",'Data R1'!AC16) | I14: =IF('Data R1'!C16="","",COUNTIF('Data R1'!J16,">0")+COUNTIF('Data R1'!L16,">0")+COUNTIF('Data R1'!N16,">0")+COUNTIF('Data R1'!P16,">0")+COUNTIF('Data R1'!R16,">0")+COUNTIF('Data R1'!T16,">0")+COUNTIF('Data R1'!V16,">0")+COUNTIF('Data R1'!X16,">0")) | J14: =IF('Data R1'!C16="","",IF((COUNTIF('Data R1'!K16,">0")+COUNTIF('Data R1'!M16,">0")+COUNTIF('Data R1'!O16,">0")+COUNTIF('Data R1'!Q16,">0")+COUNTIF('Data R1'!S16,">0")+COUNTIF('Data R1'!U16,">0")+COUNTIF('Data R1'!W16,">0")+COUNTIF('Data R1'!Y16,">0"))>0,1,0)) | L14: Pak Edi Sigit Sutarta; Pak Iput Pradiko | M14: Data R
A15: Regional 1 | B15: =IF('Data R1'!C17="","",'Data R1'!B17) | C15: =IF('Data R1'!C17="","",'Data R1'!C17) | D15: =IF('Data R1'!C17="","",'Data R1'!D17) | E15: =IF('Data R1'!C17="","",'Data R1'!E17) | F15: =IF('Data R1'!C17="","",'Data R1'!F17) | G15: =IF('Data R1'!C17="","",'Data R1'!AD17) | H15: =IF('Data R1'!C17="","",'Data R1'!AC17) | I15: =IF('Data R1'!C17="","",COUNTIF('Data R1'!J17,">0")+COUNTIF('Data R1'!L17,">0")+COUNTIF('Data R1'!N17,">0")+COUNTIF('Data R1'!P17,">0")+COUNTIF('Data R1'!R17,">0")+COUNTIF('Data R1'!T17,">0")+COUNTIF('Data R1'!V17,">0")+COUNTIF('Data R1'!X17,">0")) | J15: =IF('Data R1'!C17="","",IF((COUNTIF('Data R1'!K17,">0")+COUNTIF('Data R1'!M17,">0")+COUNTIF('Data R1'!O17,">0")+COUNTIF('Data R1'!Q17,">0")+COUNTIF('Data R1'!S17,">0")+COUNTIF('Data R1'!U17,">0")+COUNTIF('Data R1'!W17,">0")+COUNTIF('Data R1'!Y17,">0"))>0,1,0)) | L15: Pak Edi Sigit Sutarta; Pak Iput Pradiko | M15: Data R
A16: Regional 1 | B16: =IF('Data R1'!C18="","",'Data R1'!B18) | C16: =IF('Data R1'!C18="","",'Data R1'!C18) | D16: =IF('Data R1'!C18="","",'Data R1'!D18) | E16: =IF('Data R1'!C18="","",'Data R1'!E18) | F16: =IF('Data R1'!C18="","",'Data R1'!F18) | G16: =IF('Data R1'!C18="","",'Data R1'!AD18) | H16: =IF('Data R1'!C18="","",'Data R1'!AC18) | I16: =IF('Data R1'!C18="","",COUNTIF('Data R1'!J18,">0")+COUNTIF('Data R1'!L18,">0")+COUNTIF('Data R1'!N18,">0")+COUNTIF('Data R1'!P18,">0")+COUNTIF('Data R1'!R18,">0")+COUNTIF('Data R1'!T18,">0")+COUNTIF('Data R1'!V18,">0")+COUNTIF('Data R1'!X18,">0")) | J16: =IF('Data R1'!C18="","",IF((COUNTIF('Data R1'!K18,">0")+COUNTIF('Data R1'!M18,">0")+COUNTIF('Data R1'!O18,">0")+COUNTIF('Data R1'!Q18,">0")+COUNTIF('Data R1'!S18,">0")+COUNTIF('Data R1'!U18,">0")+COUNTIF('Data R1'!W18,">0")+COUNTIF('Data R1'!Y18,">0"))>0,1,0)) | L16: Pak Edi Sigit Sutarta; Pak Iput Pradiko | M16: Data R
A17: Regional 1 | B17: =IF('Data R1'!C19="","",'Data R1'!B19) | C17: =IF('Data R1'!C19="","",'Data R1'!C19) | D17: =IF('Data R1'!C19="","",'Data R1'!D19) | E17: =IF('Data R1'!C19="","",'Data R1'!E19) | F17: =IF('Data R1'!C19="","",'Data R1'!F19) | G17: =IF('Data R1'!C19="","",'Data R1'!AD19) | H17: =IF('Data R1'!C19="","",'Data R1'!AC19) | I17: =IF('Data R1'!C19="","",COUNTIF('Data R1'!J19,">0")+COUNTIF('Data R1'!L19,">0")+COUNTIF('Data R1'!N19,">0")+COUNTIF('Data R1'!P19,">0")+COUNTIF('Data R1'!R19,">0")+COUNTIF('Data R1'!T19,">0")+COUNTIF('Data R1'!V19,">0")+COUNTIF('Data R1'!X19,">0")) | J17: =IF('Data R1'!C19="","",IF((COUNTIF('Data R1'!K19,">0")+COUNTIF('Data R1'!M19,">0")+COUNTIF('Data R1'!O19,">0")+COUNTIF('Data R1'!Q19,">0")+COUNTIF('Data R1'!S19,">0")+COUNTIF('Data R1'!U19,">0")+COUNTIF('Data R1'!W19,">0")+COUNTIF('Data R1'!Y19,">0"))>0,1,0)) | M17: Data R
A18: Regional 1 | B18: =IF('Data R1'!C20="","",'Data R1'!B20) | C18: =IF('Data R1'!C20="","",'Data R1'!C20) | D18: =IF('Data R1'!C20="","",'Data R1'!D20) | E18: =IF('Data R1'!C20="","",'Data R1'!E20) | F18: =IF('Data R1'!C20="","",'Data R1'!F20) | G18: =IF('Data R1'!C20="","",'Data R1'!AD20) | H18: =IF('Data R1'!C20="","",'Data R1'!AC20) | I18: =IF('Data R1'!C20="","",COUNTIF('Data R1'!J20,">0")+COUNTIF('Data R1'!L20,">0")+COUNTIF('Data R1'!N20,">0")+COUNTIF('Data R1'!P20,">0")+COUNTIF('Data R1'!R20,">0")+COUNTIF('Data R1'!T20,">0")+COUNTIF('Data R1'!V20,">0")+COUNTIF('Data R1'!X20,">0")) | J18: =IF('Data R1'!C20="","",IF((COUNTIF('Data R1'!K20,">0")+COUNTIF('Data R1'!M20,">0")+COUNTIF('Data R1'!O20,">0")+COUNTIF('Data R1'!Q20,">0")+COUNTIF('Data R1'!S20,">0")+COUNTIF('Data R1'!U20,">0")+COUNTIF('Data R1'!W20,">0")+COUNTIF('Data R1'!Y20,">0"))>0,1,0)) | K18: Evaluasi/Kajian/Pemeriksaan | L18: Pak Edi Sigit Sutarta | M18: Data R
A19: Regional 1 | B19: =IF('Data R1'!C21="","",'Data R1'!B21) | C19: =IF('Data R1'!C21="","",'Data R1'!C21) | D19: =IF('Data R1'!C21="","",'Data R1'!D21) | E19: =IF('Data R1'!C21="","",'Data R1'!E21) | F19: =IF('Data R1'!C21="","",'Data R1'!F21) | G19: =IF('Data R1'!C21="","",'Data R1'!AD21) | H19: =IF('Data R1'!C21="","",'Data R1'!AC21) | I19: =IF('Data R1'!C21="","",COUNTIF('Data R1'!J21,">0")+COUNTIF('Data R1'!L21,">0")+COUNTIF('Data R1'!N21,">0")+COUNTIF('Data R1'!P21,">0")+COUNTIF('Data R1'!R21,">0")+COUNTIF('Data R1'!T21,">0")+COUNTIF('Data R1'!V21,">0")+COUNTIF('Data R1'!X21,">0")) | J19: =IF('Data R1'!C21="","",IF((COUNTIF('Data R1'!K21,">0")+COUNTIF('Data R1'!M21,">0")+COUNTIF('Data R1'!O21,">0")+COUNTIF('Data R1'!Q21,">0")+COUNTIF('Data R1'!S21,">0")+COUNTIF('Data R1'!U21,">0")+COUNTIF('Data R1'!W21,">0")+COUNTIF('Data R1'!Y21,">0"))>0,1,0)) | L19: Pak Edi Sigit Sutarta | M19: Data R
A20: Regional 1 | B20: =IF('Data R1'!C22="","",'Data R1'!B22) | C20: =IF('Data R1'!C22="","",'Data R1'!C22) | D20: =IF('Data R1'!C22="","",'Data R1'!D22) | E20: =IF('Data R1'!C22="","",'Data R1'!E22) | F20: =IF('Data R1'!C22="","",'Data R1'!F22) | G20: =IF('Data R1'!C22="","",'Data R1'!AD22) | H20: =IF('Data R1'!C22="","",'Data R1'!AC22) | I20: =IF('Data R1'!C22="","",COUNTIF('Data R1'!J22,">0")+COUNTIF('Data R1'!L22,">0")+COUNTIF('Data R1'!N22,">0")+COUNTIF('Data R1'!P22,">0")+COUNTIF('Data R1'!R22,">0")+COUNTIF('Data R1'!T22,">0")+COUNTIF('Data R1'!V22,">0")+COUNTIF('Data R1'!X22,">0")) | J20: =IF('Data R1'!C22="","",IF((COUNTIF('Data R1'!K22,">0")+COUNTIF('Data R1'!M22,">0")+COUNTIF('Data R1'!O22,">0")+COUNTIF('Data R1'!Q22,">0")+COUNTIF('Data R1'!S22,">0")+COUNTIF('Data R1'!U22,">0")+COUNTIF('Data R1'!W22,">0")+COUNTIF('Data R1'!Y22,">0"))>0,1,0)) | L20: Pak Edi Sigit Sutarta | M20: Data R
A21: Regional 1 | B21: =IF('Data R1'!C23="","",'Data R1'!B23) | C21: =IF('Data R1'!C23="","",'Data R1'!C23) | D21: =IF('Data R1'!C23="","",'Data R1'!D23) | E21: =IF('Data R1'!C23="","",'Data R1'!E23) | F21: =IF('Data R1'!C23="","",'Data R1'!F23) | G21: =IF('Data R1'!C23="","",'Data R1'!AD23) | H21: =IF('Data R1'!C23="","",'Data R1'!AC23) | I21: =IF('Data R1'!C23="","",COUNTIF('Data R1'!J23,">0")+COUNTIF('Data R1'!L23,">0")+COUNTIF('Data R1'!N23,">0")+COUNTIF('Data R1'!P23,">0")+COUNTIF('Data R1'!R23,">0")+COUNTIF('Data R1'!T23,">0")+COUNTIF('Data R1'!V23,">0")+COUNTIF('Data R1'!X23,">0")) | J21: =IF('Data R1'!C23="","",IF((COUNTIF('Data R1'!K23,">0")+COUNTIF('Data R1'!M23,">0")+COUNTIF('Data R1'!O23,">0")+COUNTIF('Data R1'!Q23,">0")+COUNTIF('Data R1'!S23,">0")+COUNTIF('Data R1'!U23,">0")+COUNTIF('Data R1'!W23,">0")+COUNTIF('Data R1'!Y23,">0"))>0,1,0)) | K21: Produksi / Kultur Teknis | M21: Data R
A22: Regional 1 | B22: =IF('Data R1'!C24="","",'Data R1'!B24) | C22: =IF('Data R1'!C24="","",'Data R1'!C24) | D22: =IF('Data R1'!C24="","",'Data R1'!D24) | E22: =IF('Data R1'!C24="","",'Data R1'!E24) | F22: =IF('Data R1'!C24="","",'Data R1'!F24) | G22: =IF('Data R1'!C24="","",'Data R1'!AD24) | H22: =IF('Data R1'!C24="","",'Data R1'!AC24) | I22: =IF('Data R1'!C24="","",COUNTIF('Data R1'!J24,">0")+COUNTIF('Data R1'!L24,">0")+COUNTIF('Data R1'!N24,">0")+COUNTIF('Data R1'!P24,">0")+COUNTIF('Data R1'!R24,">0")+COUNTIF('Data R1'!T24,">0")+COUNTIF('Data R1'!V24,">0")+COUNTIF('Data R1'!X24,">0")) | J22: =IF('Data R1'!C24="","",IF((COUNTIF('Data R1'!K24,">0")+COUNTIF('Data R1'!M24,">0")+COUNTIF('Data R1'!O24,">0")+COUNTIF('Data R1'!Q24,">0")+COUNTIF('Data R1'!S24,">0")+COUNTIF('Data R1'!U24,">0")+COUNTIF('Data R1'!W24,">0")+COUNTIF('Data R1'!Y24,">0"))>0,1,0)) | K22: Areal Non Produktif / Puso | L22: Pak Edi Sigit Sutarta; Pak Iput Pradiko | M22: Data R
A23: Regional 1 | B23: =IF('Data R1'!C25="","",'Data R1'!B25) | C23: =IF('Data R1'!C25="","",'Data R1'!C25) | D23: =IF('Data R1'!C25="","",'Data R1'!D25) | E23: =IF('Data R1'!C25="","",'Data R1'!E25) | F23: =IF('Data R1'!C25="","",'Data R1'!F25) | G23: =IF('Data R1'!C25="","",'Data R1'!AD25) | H23: =IF('Data R1'!C25="","",'Data R1'!AC25) | I23: =IF('Data R1'!C25="","",COUNTIF('Data R1'!J25,">0")+COUNTIF('Data R1'!L25,">0")+COUNTIF('Data R1'!N25,">0")+COUNTIF('Data R1'!P25,">0")+COUNTIF('Data R1'!R25,">0")+COUNTIF('Data R1'!T25,">0")+COUNTIF('Data R1'!V25,">0")+COUNTIF('Data R1'!X25,">0")) | J23: =IF('Data R1'!C25="","",IF((COUNTIF('Data R1'!K25,">0")+COUNTIF('Data R1'!M25,">0")+COUNTIF('Data R1'!O25,">0")+COUNTIF('Data R1'!Q25,">0")+COUNTIF('Data R1'!S25,">0")+COUNTIF('Data R1'!U25,">0")+COUNTIF('Data R1'!W25,">0")+COUNTIF('Data R1'!Y25,">0"))>0,1,0)) | K23: Areal Non Produktif / Puso | L23: Pak Edi Sigit Sutarta; Pak Iput Pradiko; Buk Nuzul Hijri | M23: Data R
A24: Regional 1 | B24: =IF('Data R1'!C26="","",'Data R1'!B26) | C24: =IF('Data R1'!C26="","",'Data R1'!C26) | D24: =IF('Data R1'!C26="","",'Data R1'!D26) | E24: =IF('Data R1'!C26="","",'Data R1'!E26) | F24: =IF('Data R1'!C26="","",'Data R1'!F26) | G24: =IF('Data R1'!C26="","",'Data R1'!AD26) | H24: =IF('Data R1'!C26="","",'Data R1'!AC26) | I24: =IF('Data R1'!C26="","",COUNTIF('Data R1'!J26,">0")+COUNTIF('Data R1'!L26,">0")+COUNTIF('Data R1'!N26,">0")+COUNTIF('Data R1'!P26,">0")+COUNTIF('Data R1'!R26,">0")+COUNTIF('Data R1'!T26,">0")+COUNTIF('Data R1'!V26,">0")+COUNTIF('Data R1'!X26,">0")) | J24: =IF('Data R1'!C26="","",IF((COUNTIF('Data R1'!K26,">0")+COUNTIF('Data R1'!M26,">0")+COUNTIF('Data R1'!O26,">0")+COUNTIF('Data R1'!Q26,">0")+COUNTIF('Data R1'!S26,">0")+COUNTIF('Data R1'!U26,">0")+COUNTIF('Data R1'!W26,">0")+COUNTIF('Data R1'!Y26,">0"))>0,1,0)) | L24: Pak Edi Sigit Sutarta; Pak Iput Pradiko; Buk Nuzul Hijri | M24: Data R
A25: Regional 1 | B25: =IF('Data R1'!C27="","",'Data R1'!B27) | C25: =IF('Data R1'!C27="","",'Data R1'!C27) | D25: =IF('Data R1'!C27="","",'Data R1'!D27) | E25: =IF('Data R1'!C27="","",'Data R1'!E27) | F25: =IF('Data R1'!C27="","",'Data R1'!F27) | G25: =IF('Data R1'!C27="","",'Data R1'!AD27) | H25: =IF('Data R1'!C27="","",'Data R1'!AC27) | I25: =IF('Data R1'!C27="","",COUNTIF('Data R1'!J27,">0")+COUNTIF('Data R1'!L27,">0")+COUNTIF('Data R1'!N27,">0")+COUNTIF('Data R1'!P27,">0")+COUNTIF('Data R1'!R27,">0")+COUNTIF('Data R1'!T27,">0")+COUNTIF('Data R1'!V27,">0")+COUNTIF('Data R1'!X27,">0")) | J25: =IF('Data R1'!C27="","",IF((COUNTIF('Data R1'!K27,">0")+COUNTIF('Data R1'!M27,">0")+COUNTIF('Data R1'!O27,">0")+COUNTIF('Data R1'!Q27,">0")+COUNTIF('Data R1'!S27,">0")+COUNTIF('Data R1'!U27,">0")+COUNTIF('Data R1'!W27,">0")+COUNTIF('Data R1'!Y27,">0"))>0,1,0)) | L25: Pak Edi Sigit Sutarta; Pak Iput Pradiko; Buk Nuzul Hijri | M25: Data R
A26: Regional 1 | B26: =IF('Data R1'!C28="","",'Data R1'!B28) | C26: =IF('Data R1'!C28="","",'Data R1'!C28) | D26: =IF('Data R1'!C28="","",'Data R1'!D28) | E26: =IF('Data R1'!C28="","",'Data R1'!E28) | F26: =IF('Data R1'!C28="","",'Data R1'!F28) | G26: =IF('Data R1'!C28="","",'Data R1'!AD28) | H26: =IF('Data R1'!C28="","",'Data R1'!AC28) | I26: =IF('Data R1'!C28="","",COUNTIF('Data R1'!J28,">0")+COUNTIF('Data R1'!L28,">0")+COUNTIF('Data R1'!N28,">0")+COUNTIF('Data R1'!P28,">0")+COUNTIF('Data R1'!R28,">0")+COUNTIF('Data R1'!T28,">0")+COUNTIF('Data R1'!V28,">0")+COUNTIF('Data R1'!X28,">0")) | J26: =IF('Data R1'!C28="","",IF((COUNTIF('Data R1'!K28,">0")+COUNTIF('Data R1'!M28,">0")+COUNTIF('Data R1'!O28,">0")+COUNTIF('Data R1'!Q28,">0")+COUNTIF('Data R1'!S28,">0")+COUNTIF('Data R1'!U28,">0")+COUNTIF('Data R1'!W28,">0")+COUNTIF('Data R1'!Y28,">0"))>0,1,0)) | K26: Tanam Ulang / Program TU | L26: Pak Edi Sigit Sutarta; Pak Iput Pradiko | M26: Data R
A27: Regional 1 | B27: =IF('Data R1'!C29="","",'Data R1'!B29) | C27: =IF('Data R1'!C29="","",'Data R1'!C29) | D27: =IF('Data R1'!C29="","",'Data R1'!D29) | E27: =IF('Data R1'!C29="","",'Data R1'!E29) | F27: =IF('Data R1'!C29="","",'Data R1'!F29) | G27: =IF('Data R1'!C29="","",'Data R1'!AD29) | H27: =IF('Data R1'!C29="","",'Data R1'!AC29) | I27: =IF('Data R1'!C29="","",COUNTIF('Data R1'!J29,">0")+COUNTIF('Data R1'!L29,">0")+COUNTIF('Data R1'!N29,">0")+COUNTIF('Data R1'!P29,">0")+COUNTIF('Data R1'!R29,">0")+COUNTIF('Data R1'!T29,">0")+COUNTIF('Data R1'!V29,">0")+COUNTIF('Data R1'!X29,">0")) | J27: =IF('Data R1'!C29="","",IF((COUNTIF('Data R1'!K29,">0")+COUNTIF('Data R1'!M29,">0")+COUNTIF('Data R1'!O29,">0")+COUNTIF('Data R1'!Q29,">0")+COUNTIF('Data R1'!S29,">0")+COUNTIF('Data R1'!U29,">0")+COUNTIF('Data R1'!W29,">0")+COUNTIF('Data R1'!Y29,">0"))>0,1,0)) | L27: Pak Edi Sigit Sutarta; Pak Iput Pradiko | M27: Data R
A28: Regional 1 | B28: =IF('Data R1'!C30="","",'Data R1'!B30) | C28: =IF('Data R1'!C30="","",'Data R1'!C30) | D28: =IF('Data R1'!C30="","",'Data R1'!D30) | E28: =IF('Data R1'!C30="","",'Data R1'!E30) | F28: =IF('Data R1'!C30="","",'Data R1'!F30) | G28: =IF('Data R1'!C30="","",'Data R1'!AD30) | H28: =IF('Data R1'!C30="","",'Data R1'!AC30) | I28: =IF('Data R1'!C30="","",COUNTIF('Data R1'!J30,">0")+COUNTIF('Data R1'!L30,">0")+COUNTIF('Data R1'!N30,">0")+COUNTIF('Data R1'!P30,">0")+COUNTIF('Data R1'!R30,">0")+COUNTIF('Data R1'!T30,">0")+COUNTIF('Data R1'!V30,">0")+COUNTIF('Data R1'!X30,">0")) | J28: =IF('Data R1'!C30="","",IF((COUNTIF('Data R1'!K30,">0")+COUNTIF('Data R1'!M30,">0")+COUNTIF('Data R1'!O30,">0")+COUNTIF('Data R1'!Q30,">0")+COUNTIF('Data R1'!S30,">0")+COUNTIF('Data R1'!U30,">0")+COUNTIF('Data R1'!W30,">0")+COUNTIF('Data R1'!Y30,">0"))>0,1,0)) | L28: Pak Edi Sigit Sutarta; Pak Iput Pradiko | M28: Data R
A29: Regional 1 | B29: =IF('Data R1'!C31="","",'Data R1'!B31) | C29: =IF('Data R1'!C31="","",'Data R1'!C31) | D29: =IF('Data R1'!C31="","",'Data R1'!D31) | E29: =IF('Data R1'!C31="","",'Data R1'!E31) | F29: =IF('Data R1'!C31="","",'Data R1'!F31) | G29: =IF('Data R1'!C31="","",'Data R1'!AD31) | H29: =IF('Data R1'!C31="","",'Data R1'!AC31) | I29: =IF('Data R1'!C31="","",COUNTIF('Data R1'!J31,">0")+COUNTIF('Data R1'!L31,">0")+COUNTIF('Data R1'!N31,">0")+COUNTIF('Data R1'!P31,">0")+COUNTIF('Data R1'!R31,">0")+COUNTIF('Data R1'!T31,">0")+COUNTIF('Data R1'!V31,">0")+COUNTIF('Data R1'!X31,">0")) | J29: =IF('Data R1'!C31="","",IF((COUNTIF('Data R1'!K31,">0")+COUNTIF('Data R1'!M31,">0")+COUNTIF('Data R1'!O31,">0")+COUNTIF('Data R1'!Q31,">0")+COUNTIF('Data R1'!S31,">0")+COUNTIF('Data R1'!U31,">0")+COUNTIF('Data R1'!W31,">0")+COUNTIF('Data R1'!Y31,">0"))>0,1,0)) | L29: Pak Edi Sigit Sutarta; Pak Iput Pradiko | M29: Data R
A30: Regional 1 | B30: =IF('Data R1'!C32="","",'Data R1'!B32) | C30: =IF('Data R1'!C32="","",'Data R1'!C32) | D30: =IF('Data R1'!C32="","",'Data R1'!D32) | E30: =IF('Data R1'!C32="","",'Data R1'!E32) | F30: =IF('Data R1'!C32="","",'Data R1'!F32) | G30: =IF('Data R1'!C32="","",'Data R1'!AD32) | H30: =IF('Data R1'!C32="","",'Data R1'!AC32) | I30: =IF('Data R1'!C32="","",COUNTIF('Data R1'!J32,">0")+COUNTIF('Data R1'!L32,">0")+COUNTIF('Data R1'!N32,">0")+COUNTIF('Data R1'!P32,">0")+COUNTIF('Data R1'!R32,">0")+COUNTIF('Data R1'!T32,">0")+COUNTIF('Data R1'!V32,">0")+COUNTIF('Data R1'!X32,">0")) | J30: =IF('Data R1'!C32="","",IF((COUNTIF('Data R1'!K32,">0")+COUNTIF('Data R1'!M32,">0")+COUNTIF('Data R1'!O32,">0")+COUNTIF('Data R1'!Q32,">0")+COUNTIF('Data R1'!S32,">0")+COUNTIF('Data R1'!U32,">0")+COUNTIF('Data R1'!W32,">0")+COUNTIF('Data R1'!Y32,">0"))>0,1,0)) | L30: Pak Edi Sigit Sutarta; Pak Iput Pradiko | M30: Data R
A31: Regional 1 | B31: =IF('Data R1'!C33="","",'Data R1'!B33) | C31: =IF('Data R1'!C33="","",'Data R1'!C33) | D31: =IF('Data R1'!C33="","",'Data R1'!D33) | E31: =IF('Data R1'!C33="","",'Data R1'!E33) | F31: =IF('Data R1'!C33="","",'Data R1'!F33) | G31: =IF('Data R1'!C33="","",'Data R1'!AD33) | H31: =IF('Data R1'!C33="","",'Data R1'!AC33) | I31: =IF('Data R1'!C33="","",COUNTIF('Data R1'!J33,">0")+COUNTIF('Data R1'!L33,">0")+COUNTIF('Data R1'!N33,">0")+COUNTIF('Data R1'!P33,">0")+COUNTIF('Data R1'!R33,">0")+COUNTIF('Data R1'!T33,">0")+COUNTIF('Data R1'!V33,">0")+COUNTIF('Data R1'!X33,">0")) | J31: =IF('Data R1'!C33="","",IF((COUNTIF('Data R1'!K33,">0")+COUNTIF('Data R1'!M33,">0")+COUNTIF('Data R1'!O33,">0")+COUNTIF('Data R1'!Q33,">0")+COUNTIF('Data R1'!S33,">0")+COUNTIF('Data R1'!U33,">0")+COUNTIF('Data R1'!W33,">0")+COUNTIF('Data R1'!Y33,">0"))>0,1,0)) | L31: Pak Edi Sigit Sutarta; Pak Iput Pradiko | M31: Data R
A32: Regional 1 | B32: =IF('Data R1'!C34="","",'Data R1'!B34) | C32: =IF('Data R1'!C34="","",'Data R1'!C34) | D32: =IF('Data R1'!C34="","",'Data R1'!D34) | E32: =IF('Data R1'!C34="","",'Data R1'!E34) | F32: =IF('Data R1'!C34="","",'Data R1'!F34) | G32: =IF('Data R1'!C34="","",'Data R1'!AD34) | H32: =IF('Data R1'!C34="","",'Data R1'!AC34) | I32: =IF('Data R1'!C34="","",COUNTIF('Data R1'!J34,">0")+COUNTIF('Data R1'!L34,">0")+COUNTIF('Data R1'!N34,">0")+COUNTIF('Data R1'!P34,">0")+COUNTIF('Data R1'!R34,">0")+COUNTIF('Data R1'!T34,">0")+COUNTIF('Data R1'!V34,">0")+COUNTIF('Data R1'!X34,">0")) | J32: =IF('Data R1'!C34="","",IF((COUNTIF('Data R1'!K34,">0")+COUNTIF('Data R1'!M34,">0")+COUNTIF('Data R1'!O34,">0")+COUNTIF('Data R1'!Q34,">0")+COUNTIF('Data R1'!S34,">0")+COUNTIF('Data R1'!U34,">0")+COUNTIF('Data R1'!W34,">0")+COUNTIF('Data R1'!Y34,">0"))>0,1,0)) | K32: Evaluasi/Kajian/Pemeriksaan | M32: Data R
A33: Regional 1 | B33: =IF('Data R1'!C35="","",'Data R1'!B35) | C33: =IF('Data R1'!C35="","",'Data R1'!C35) | D33: =IF('Data R1'!C35="","",'Data R1'!D35) | E33: =IF('Data R1'!C35="","",'Data R1'!E35) | F33: =IF('Data R1'!C35="","",'Data R1'!F35) | G33: =IF('Data R1'!C35="","",'Data R1'!AD35) | H33: =IF('Data R1'!C35="","",'Data R1'!AC35) | I33: =IF('Data R1'!C35="","",COUNTIF('Data R1'!J35,">0")+COUNTIF('Data R1'!L35,">0")+COUNTIF('Data R1'!N35,">0")+COUNTIF('Data R1'!P35,">0")+COUNTIF('Data R1'!R35,">0")+COUNTIF('Data R1'!T35,">0")+COUNTIF('Data R1'!V35,">0")+COUNTIF('Data R1'!X35,">0")) | J33: =IF('Data R1'!C35="","",IF((COUNTIF('Data R1'!K35,">0")+COUNTIF('Data R1'!M35,">0")+COUNTIF('Data R1'!O35,">0")+COUNTIF('Data R1'!Q35,">0")+COUNTIF('Data R1'!S35,">0")+COUNTIF('Data R1'!U35,">0")+COUNTIF('Data R1'!W35,">0")+COUNTIF('Data R1'!Y35,">0"))>0,1,0)) | K33: Produksi / Kultur Teknis | M33: Data R
A34: Regional 1 | B34: =IF('Data R1'!C36="","",'Data R1'!B36) | C34: =IF('Data R1'!C36="","",'Data R1'!C36) | D34: =IF('Data R1'!C36="","",'Data R1'!D36) | E34: =IF('Data R1'!C36="","",'Data R1'!E36) | F34: =IF('Data R1'!C36="","",'Data R1'!F36) | G34: =IF('Data R1'!C36="","",'Data R1'!AD36) | H34: =IF('Data R1'!C36="","",'Data R1'!AC36) | I34: =IF('Data R1'!C36="","",COUNTIF('Data R1'!J36,">0")+COUNTIF('Data R1'!L36,">0")+COUNTIF('Data R1'!N36,">0")+COUNTIF('Data R1'!P36,">0")+COUNTIF('Data R1'!R36,">0")+COUNTIF('Data R1'!T36,">0")+COUNTIF('Data R1'!V36,">0")+COUNTIF('Data R1'!X36,">0")) | J34: =IF('Data R1'!C36="","",IF((COUNTIF('Data R1'!K36,">0")+COUNTIF('Data R1'!M36,">0")+COUNTIF('Data R1'!O36,">0")+COUNTIF('Data R1'!Q36,">0")+COUNTIF('Data R1'!S36,">0")+COUNTIF('Data R1'!U36,">0")+COUNTIF('Data R1'!W36,">0")+COUNTIF('Data R1'!Y36,">0"))>0,1,0)) | M34: Data R
A35: Regional 1 | B35: =IF('Data R1'!C37="","",'Data R1'!B37) | C35: =IF('Data R1'!C37="","",'Data R1'!C37) | D35: =IF('Data R1'!C37="","",'Data R1'!D37) | E35: =IF('Data R1'!C37="","",'Data R1'!E37) | F35: =IF('Data R1'!C37="","",'Data R1'!F37) | G35: =IF('Data R1'!C37="","",'Data R1'!AD37) | H35: =IF('Data R1'!C37="","",'Data R1'!AC37) | I35: =IF('Data R1'!C37="","",COUNTIF('Data R1'!J37,">0")+COUNTIF('Data R1'!L37,">0")+COUNTIF('Data R1'!N37,">0")+COUNTIF('Data R1'!P37,">0")+COUNTIF('Data R1'!R37,">0")+COUNTIF('Data R1'!T37,">0")+COUNTIF('Data R1'!V37,">0")+COUNTIF('Data R1'!X37,">0")) | J35: =IF('Data R1'!C37="","",IF((COUNTIF('Data R1'!K37,">0")+COUNTIF('Data R1'!M37,">0")+COUNTIF('Data R1'!O37,">0")+COUNTIF('Data R1'!Q37,">0")+COUNTIF('Data R1'!S37,">0")+COUNTIF('Data R1'!U37,">0")+COUNTIF('Data R1'!W37,">0")+COUNTIF('Data R1'!Y37,">0"))>0,1,0)) | M35: Data R
A36: Regional 1 | B36: =IF('Data R1'!C38="","",'Data R1'!B38) | C36: =IF('Data R1'!C38="","",'Data R1'!C38) | D36: =IF('Data R1'!C38="","",'Data R1'!D38) | E36: =IF('Data R1'!C38="","",'Data R1'!E38) | F36: =IF('Data R1'!C38="","",'Data R1'!F38) | G36: =IF('Data R1'!C38="","",'Data R1'!AD38) | H36: =IF('Data R1'!C38="","",'Data R1'!AC38) | I36: =IF('Data R1'!C38="","",COUNTIF('Data R1'!J38,">0")+COUNTIF('Data R1'!L38,">0")+COUNTIF('Data R1'!N38,">0")+COUNTIF('Data R1'!P38,">0")+COUNTIF('Data R1'!R38,">0")+COUNTIF('Data R1'!T38,">0")+COUNTIF('Data R1'!V38,">0")+COUNTIF('Data R1'!X38,">0")) | J36: =IF('Data R1'!C38="","",IF((COUNTIF('Data R1'!K38,">0")+COUNTIF('Data R1'!M38,">0")+COUNTIF('Data R1'!O38,">0")+COUNTIF('Data R1'!Q38,">0")+COUNTIF('Data R1'!S38,">0")+COUNTIF('Data R1'!U38,">0")+COUNTIF('Data R1'!W38,">0")+COUNTIF('Data R1'!Y38,">0"))>0,1,0)) | M36: Data R
A37: Regional 1 | B37: =IF('Data R1'!C39="","",'Data R1'!B39) | C37: =IF('Data R1'!C39="","",'Data R1'!C39) | D37: =IF('Data R1'!C39="","",'Data R1'!D39) | E37: =IF('Data R1'!C39="","",'Data R1'!E39) | F37: =IF('Data R1'!C39="","",'Data R1'!F39) | G37: =IF('Data R1'!C39="","",'Data R1'!AD39) | H37: =IF('Data R1'!C39="","",'Data R1'!AC39) | I37: =IF('Data R1'!C39="","",COUNTIF('Data R1'!J39,">0")+COUNTIF('Data R1'!L39,">0")+COUNTIF('Data R1'!N39,">0")+COUNTIF('Data R1'!P39,">0")+COUNTIF('Data R1'!R39,">0")+COUNTIF('Data R1'!T39,">0")+COUNTIF('Data R1'!V39,">0")+COUNTIF('Data R1'!X39,">0")) | J37: =IF('Data R1'!C39="","",IF((COUNTIF('Data R1'!K39,">0")+COUNTIF('Data R1'!M39,">0")+COUNTIF('Data R1'!O39,">0")+COUNTIF('Data R1'!Q39,">0")+COUNTIF('Data R1'!S39,">0")+COUNTIF('Data R1'!U39,">0")+COUNTIF('Data R1'!W39,">0")+COUNTIF('Data R1'!Y39,">0"))>0,1,0)) | M37: Data R
A38: Regional 1 | B38: =IF('Data R1'!C40="","",'Data R1'!B40) | C38: =IF('Data R1'!C40="","",'Data R1'!C40) | D38: =IF('Data R1'!C40="","",'Data R1'!D40) | E38: =IF('Data R1'!C40="","",'Data R1'!E40) | F38: =IF('Data R1'!C40="","",'Data R1'!F40) | G38: =IF('Data R1'!C40="","",'Data R1'!AD40) | H38: =IF('Data R1'!C40="","",'Data R1'!AC40) | I38: =IF('Data R1'!C40="","",COUNTIF('Data R1'!J40,">0")+COUNTIF('Data R1'!L40,">0")+COUNTIF('Data R1'!N40,">0")+COUNTIF('Data R1'!P40,">0")+COUNTIF('Data R1'!R40,">0")+COUNTIF('Data R1'!T40,">0")+COUNTIF('Data R1'!V40,">0")+COUNTIF('Data R1'!X40,">0")) | J38: =IF('Data R1'!C40="","",IF((COUNTIF('Data R1'!K40,">0")+COUNTIF('Data R1'!M40,">0")+COUNTIF('Data R1'!O40,">0")+COUNTIF('Data R1'!Q40,">0")+COUNTIF('Data R1'!S40,">0")+COUNTIF('Data R1'!U40,">0")+COUNTIF('Data R1'!W40,">0")+COUNTIF('Data R1'!Y40,">0"))>0,1,0)) | M38: Data R
A39: Regional 1 | B39: =IF('Data R1'!C41="","",'Data R1'!B41) | C39: =IF('Data R1'!C41="","",'Data R1'!C41) | D39: =IF('Data R1'!C41="","",'Data R1'!D41) | E39: =IF('Data R1'!C41="","",'Data R1'!E41) | F39: =IF('Data R1'!C41="","",'Data R1'!F41) | G39: =IF('Data R1'!C41="","",'Data R1'!AD41) | H39: =IF('Data R1'!C41="","",'Data R1'!AC41) | I39: =IF('Data R1'!C41="","",COUNTIF('Data R1'!J41,">0")+COUNTIF('Data R1'!L41,">0")+COUNTIF('Data R1'!N41,">0")+COUNTIF('Data R1'!P41,">0")+COUNTIF('Data R1'!R41,">0")+COUNTIF('Data R1'!T41,">0")+COUNTIF('Data R1'!V41,">0")+COUNTIF('Data R1'!X41,">0")) | J39: =IF('Data R1'!C41="","",IF((COUNTIF('Data R1'!K41,">0")+COUNTIF('Data R1'!M41,">0")+COUNTIF('Data R1'!O41,">0")+COUNTIF('Data R1'!Q41,">0")+COUNTIF('Data R1'!S41,">0")+COUNTIF('Data R1'!U41,">0")+COUNTIF('Data R1'!W41,">0")+COUNTIF('Data R1'!Y41,">0"))>0,1,0)) | M39: Data R
A40: Regional 1 | B40: =IF('Data R1'!C42="","",'Data R1'!B42) | C40: =IF('Data R1'!C42="","",'Data R1'!C42) | D40: =IF('Data R1'!C42="","",'Data R1'!D42) | E40: =IF('Data R1'!C42="","",'Data R1'!E42) | F40: =IF('Data R1'!C42="","",'Data R1'!F42) | G40: =IF('Data R1'!C42="","",'Data R1'!AD42) | H40: =IF('Data R1'!C42="","",'Data R1'!AC42) | I40: =IF('Data R1'!C42="","",COUNTIF('Data R1'!J42,">0")+COUNTIF('Data R1'!L42,">0")+COUNTIF('Data R1'!N42,">0")+COUNTIF('Data R1'!P42,">0")+COUNTIF('Data R1'!R42,">0")+COUNTIF('Data R1'!T42,">0")+COUNTIF('Data R1'!V42,">0")+COUNTIF('Data R1'!X42,">0")) | J40: =IF('Data R1'!C42="","",IF((COUNTIF('Data R1'!K42,">0")+COUNTIF('Data R1'!M42,">0")+COUNTIF('Data R1'!O42,">0")+COUNTIF('Data R1'!Q42,">0")+COUNTIF('Data R1'!S42,">0")+COUNTIF('Data R1'!U42,">0")+COUNTIF('Data R1'!W42,">0")+COUNTIF('Data R1'!Y42,">0"))>0,1,0)) | M40: Data R
...

Sheet RINGKASAN
A1: MONITORING LAPORAN BANTUAN TEKNIS
A2: Urusan Pelayanan Jasa Konsultansi dan Pelatihan (otomatis ter-update s.d 1000 baris/sheet)
A4: STATISTIK KESELURUHAN
A5: Total Data: | B5: Sudah Dikirim: | C5: Masih Proses:
A6: =COUNTA('Data R1'!$C$4:$C$1001)+COUNTA('Data R2'!$C$4:$C$1001)+COUNTA('Data R3'!$C$4:$C$1001)+COUNTA('Data R4'!$C$4:$C$1001)+COUNTA('Data R5'!$C$4:$C$1001)+COUNTA('Data R6'!$C$4:$C$1001)+COUNTA('Data R7'!$C$4:$C$1001)+COUNTA('Data R4P'!$C$4:$C$1001)+COUNTA('Data SW'!$C$4:$C$1001) | B6: =COUNTIF('Data R1'!$AC$4:$AC$1001,"SELESAI")+COUNTIF('Data R2'!$AC$4:$AC$1001,"SELESAI")+COUNTIF('Data R3'!$AC$4:$AC$1001,"SELESAI")+COUNTIF('Data R4'!$AC$4:$AC$1001,"SELESAI")+COUNTIF('Data R5'!$AC$4:$AC$1001,"SELESAI")+COUNTIF('Data R6'!$AC$4:$AC$1001,"SELESAI")+COUNTIF('Data R7'!$AC$4:$AC$1001,"SELESAI")+COUNTIF('Data R4P'!$AC$4:$AC$1001,"SELESAI")+COUNTIF('Data SW'!$AC$4:$AC$1001,"SELESAI") | C6: =COUNTIF('Data R1'!$AC$4:$AC$1001,"PROSES")+COUNTIF('Data R2'!$AC$4:$AC$1001,"PROSES")+COUNTIF('Data R3'!$AC$4:$AC$1001,"PROSES")+COUNTIF('Data R4'!$AC$4:$AC$1001,"PROSES")+COUNTIF('Data R5'!$AC$4:$AC$1001,"PROSES")+COUNTIF('Data R6'!$AC$4:$AC$1001,"PROSES")+COUNTIF('Data R7'!$AC$4:$AC$1001,"PROSES")+COUNTIF('Data R4P'!$AC$4:$AC$1001,"PROSES")+COUNTIF('Data SW'!$AC$4:$AC$1001,"PROSES")
A8: % Selesai: | B8: =IF((COUNTA('Data R1'!$C$4:$C$1001)+COUNTA('Data R2'!$C$4:$C$1001)+COUNTA('Data R3'!$C$4:$C$1001)+COUNTA('Data R4'!$C$4:$C$1001)+COUNTA('Data R5'!$C$4:$C$1001)+COUNTA('Data R6'!$C$4:$C$1001)+COUNTA('Data R7'!$C$4:$C$1001)+COUNTA('Data R4P'!$C$4:$C$1001)+COUNTA('Data SW'!$C$4:$C$1001))=0,0,ROUND((COUNTIF('Data R1'!$AC$4:$AC$1001,"SELESAI")+COUNTIF('Data R2'!$AC$4:$AC$1001,"SELESAI")+COUNTIF('Data R3'!$AC$4:$AC$1001,"SELESAI")+COUNTIF('Data R4'!$AC$4:$AC$1001,"SELESAI")+COUNTIF('Data R5'!$AC$4:$AC$1001,"SELESAI")+COUNTIF('Data R6'!$AC$4:$AC$1001,"SELESAI")+COUNTIF('Data R7'!$AC$4:$AC$1001,"SELESAI")+COUNTIF('Data R4P'!$AC$4:$AC$1001,"SELESAI")+COUNTIF('Data SW'!$AC$4:$AC$1001,"SELESAI"))/(COUNTA('Data R1'!$C$4:$C$1001)+COUNTA('Data R2'!$C$4:$C$1001)+COUNTA('Data R3'!$C$4:$C$1001)+COUNTA('Data R4'!$C$4:$C$1001)+COUNTA('Data R5'!$C$4:$C$1001)+COUNTA('Data R6'!$C$4:$C$1001)+COUNTA('Data R7'!$C$4:$C$1001)+COUNTA('Data R4P'!$C$4:$C$1001)+COUNTA('Data SW'!$C$4:$C$1001))*100,0)) | C8: %
A10: RINGKASAN PER REGIONAL (otomatis)
A11: Regional | B11: Total | C11: Draft Masuk | D11: Dikoreksi | E11: Direvisi | F11: Dicetak | G11: Sudah Dikirim | H11: % Selesai | I11: Sheet
A12: Regional 1 | B12: =COUNTA('Data R1'!$C$4:$C$1001) | C12: =COUNTIF('Data R1'!$G$4:$G$1001,"<>") | D12: =COUNTIF('Data R1'!$J$4:$J$1001,"<>") | E12: =COUNTIF('Data R1'!$Z$4:$Z$1001,"<>") | F12: =COUNTIF('Data R1'!$AA$4:$AA$1001,"<>") | G12: =COUNTIF('Data R1'!$AB$4:$AB$1001,"<>") | H12: =IF(COUNTA('Data R1'!$C$4:$C$1001)=0,0,ROUND(COUNTIF('Data R1'!$AB$4:$AB$1001,"<>")/COUNTA('Data R1'!$C$4:$C$1001)*100,0)) | I12: Data R1
A13: Regional 2 | B13: =COUNTA('Data R2'!$C$4:$C$1001) | C13: =COUNTIF('Data R2'!$G$4:$G$1001,"<>") | D13: =COUNTIF('Data R2'!$J$4:$J$1001,"<>") | E13: =COUNTIF('Data R2'!$Z$4:$Z$1001,"<>") | F13: =COUNTIF('Data R2'!$AA$4:$AA$1001,"<>") | G13: =COUNTIF('Data R2'!$AB$4:$AB$1001,"<>") | H13: =IF(COUNTA('Data R2'!$C$4:$C$1001)=0,0,ROUND(COUNTIF('Data R2'!$AB$4:$AB$1001,"<>")/COUNTA('Data R2'!$C$4:$C$1001)*100,0)) | I13: Data R2
A14: Regional 3 | B14: =COUNTA('Data R3'!$C$4:$C$1001) | C14: =COUNTIF('Data R3'!$G$4:$G$1001,"<>") | D14: =COUNTIF('Data R3'!$J$4:$J$1001,"<>") | E14: =COUNTIF('Data R3'!$Z$4:$Z$1001,"<>") | F14: =COUNTIF('Data R3'!$AA$4:$AA$1001,"<>") | G14: =COUNTIF('Data R3'!$AB$4:$AB$1001,"<>") | H14: =IF(COUNTA('Data R3'!$C$4:$C$1001)=0,0,ROUND(COUNTIF('Data R3'!$AB$4:$AB$1001,"<>")/COUNTA('Data R3'!$C$4:$C$1001)*100,0)) | I14: Data R3
A15: Regional 4 | B15: =COUNTA('Data R4'!$C$4:$C$1001) | C15: =COUNTIF('Data R4'!$G$4:$G$1001,"<>") | D15: =COUNTIF('Data R4'!$J$4:$J$1001,"<>") | E15: =COUNTIF('Data R4'!$Z$4:$Z$1001,"<>") | F15: =COUNTIF('Data R4'!$AA$4:$AA$1001,"<>") | G15: =COUNTIF('Data R4'!$AB$4:$AB$1001,"<>") | H15: =IF(COUNTA('Data R4'!$C$4:$C$1001)=0,0,ROUND(COUNTIF('Data R4'!$AB$4:$AB$1001,"<>")/COUNTA('Data R4'!$C$4:$C$1001)*100,0)) | I15: Data R4
A16: Regional 5 | B16: =COUNTA('Data R5'!$C$4:$C$1001) | C16: =COUNTIF('Data R5'!$G$4:$G$1001,"<>") | D16: =COUNTIF('Data R5'!$J$4:$J$1001,"<>") | E16: =COUNTIF('Data R5'!$Z$4:$Z$1001,"<>") | F16: =COUNTIF('Data R5'!$AA$4:$AA$1001,"<>") | G16: =COUNTIF('Data R5'!$AB$4:$AB$1001,"<>") | H16: =IF(COUNTA('Data R5'!$C$4:$C$1001)=0,0,ROUND(COUNTIF('Data R5'!$AB$4:$AB$1001,"<>")/COUNTA('Data R5'!$C$4:$C$1001)*100,0)) | I16: Data R5
A17: Regional 6 | B17: =COUNTA('Data R6'!$C$4:$C$1001) | C17: =COUNTIF('Data R6'!$G$4:$G$1001,"<>") | D17: =COUNTIF('Data R6'!$J$4:$J$1001,"<>") | E17: =COUNTIF('Data R6'!$Z$4:$Z$1001,"<>") | F17: =COUNTIF('Data R6'!$AA$4:$AA$1001,"<>") | G17: =COUNTIF('Data R6'!$AB$4:$AB$1001,"<>") | H17: =IF(COUNTA('Data R6'!$C$4:$C$1001)=0,0,ROUND(COUNTIF('Data R6'!$AB$4:$AB$1001,"<>")/COUNTA('Data R6'!$C$4:$C$1001)*100,0)) | I17: Data R6
A18: Regional 7 | B18: =COUNTA('Data R7'!$C$4:$C$1001) | C18: =COUNTIF('Data R7'!$G$4:$G$1001,"<>") | D18: =COUNTIF('Data R7'!$J$4:$J$1001,"<>") | E18: =COUNTIF('Data R7'!$Z$4:$Z$1001,"<>") | F18: =COUNTIF('Data R7'!$AA$4:$AA$1001,"<>") | G18: =COUNTIF('Data R7'!$AB$4:$AB$1001,"<>") | H18: =IF(COUNTA('Data R7'!$C$4:$C$1001)=0,0,ROUND(COUNTIF('Data R7'!$AB$4:$AB$1001,"<>")/COUNTA('Data R7'!$C$4:$C$1001)*100,0)) | I18: Data R7
A19: Regional 4 Palmco | B19: =COUNTA('Data R4P'!$C$4:$C$1001) | C19: =COUNTIF('Data R4P'!$G$4:$G$1001,"<>") | D19: =COUNTIF('Data R4P'!$J$4:$J$1001,"<>") | E19: =COUNTIF('Data R4P'!$Z$4:$Z$1001,"<>") | F19: =COUNTIF('Data R4P'!$AA$4:$AA$1001,"<>") | G19: =COUNTIF('Data R4P'!$AB$4:$AB$1001,"<>") | H19: =IF(COUNTA('Data R4P'!$C$4:$C$1001)=0,0,ROUND(COUNTIF('Data R4P'!$AB$4:$AB$1001,"<>")/COUNTA('Data R4P'!$C$4:$C$1001)*100,0)) | I19: Data R4P
A20: Swasta/PPKS | B20: =COUNTA('Data SW'!$C$4:$C$1001) | C20: =COUNTIF('Data SW'!$G$4:$G$1001,"<>") | D20: =COUNTIF('Data SW'!$J$4:$J$1001,"<>") | E20: =COUNTIF('Data SW'!$Z$4:$Z$1001,"<>") | F20: =COUNTIF('Data SW'!$AA$4:$AA$1001,"<>") | G20: =COUNTIF('Data SW'!$AB$4:$AB$1001,"<>") | H20: =IF(COUNTA('Data SW'!$C$4:$C$1001)=0,0,ROUND(COUNTIF('Data SW'!$AB$4:$AB$1001,"<>")/COUNTA('Data SW'!$C$4:$C$1001)*100,0)) | I20: Data SW
A21: TOTAL | B21: =COUNTA('Data R1'!$C$4:$C$1001)+COUNTA('Data R2'!$C$4:$C$1001)+COUNTA('Data R3'!$C$4:$C$1001)+COUNTA('Data R4'!$C$4:$C$1001)+COUNTA('Data R5'!$C$4:$C$1001)+COUNTA('Data R6'!$C$4:$C$1001)+COUNTA('Data R7'!$C$4:$C$1001)+COUNTA('Data R4P'!$C$4:$C$1001)+COUNTA('Data SW'!$C$4:$C$1001) | C21: =COUNTIF('Data R1'!$G$4:$G$1001,"<>")+COUNTIF('Data R2'!$G$4:$G$1001,"<>")+COUNTIF('Data R3'!$G$4:$G$1001,"<>")+COUNTIF('Data R4'!$G$4:$G$1001,"<>")+COUNTIF('Data R5'!$G$4:$G$1001,"<>")+COUNTIF('Data R6'!$G$4:$G$1001,"<>")+COUNTIF('Data R7'!$G$4:$G$1001,"<>")+COUNTIF('Data R4P'!$G$4:$G$1001,"<>")+COUNTIF('Data SW'!$G$4:$G$1001,"<>") | D21: =COUNTIF('Data R1'!$J$4:$J$1001,"<>")+COUNTIF('Data R2'!$J$4:$J$1001,"<>")+COUNTIF('Data R3'!$J$4:$J$1001,"<>")+COUNTIF('Data R4'!$J$4:$J$1001,"<>")+COUNTIF('Data R5'!$J$4:$J$1001,"<>")+COUNTIF('Data R6'!$J$4:$J$1001,"<>")+COUNTIF('Data R7'!$J$4:$J$1001,"<>")+COUNTIF('Data R4P'!$J$4:$J$1001,"<>")+COUNTIF('Data SW'!$J$4:$J$1001,"<>") | E21: =COUNTIF('Data R1'!$Z$4:$Z$1001,"<>")+COUNTIF('Data R2'!$Z$4:$Z$1001,"<>")+COUNTIF('Data R3'!$Z$4:$Z$1001,"<>")+COUNTIF('Data R4'!$Z$4:$Z$1001,"<>")+COUNTIF('Data R5'!$Z$4:$Z$1001,"<>")+COUNTIF('Data R6'!$Z$4:$Z$1001,"<>")+COUNTIF('Data R7'!$Z$4:$Z$1001,"<>")+COUNTIF('Data R4P'!$Z$4:$Z$1001,"<>")+COUNTIF('Data SW'!$Z$4:$Z$1001,"<>") | F21: =COUNTIF('Data R1'!$AA$4:$AA$1001,"<>")+COUNTIF('Data R2'!$AA$4:$AA$1001,"<>")+COUNTIF('Data R3'!$AA$4:$AA$1001,"<>")+COUNTIF('Data R4'!$AA$4:$AA$1001,"<>")+COUNTIF('Data R5'!$AA$4:$AA$1001,"<>")+COUNTIF('Data R6'!$AA$4:$AA$1001,"<>")+COUNTIF('Data R7'!$AA$4:$AA$1001,"<>")+COUNTIF('Data R4P'!$AA$4:$AA$1001,"<>")+COUNTIF('Data SW'!$AA$4:$AA$1001,"<>") | G21: =COUNTIF('Data R1'!$AB$4:$AB$1001,"<>")+COUNTIF('Data R2'!$AB$4:$AB$1001,"<>")+COUNTIF('Data R3'!$AB$4:$AB$1001,"<>")+COUNTIF('Data R4'!$AB$4:$AB$1001,"<>")+COUNTIF('Data R5'!$AB$4:$AB$1001,"<>")+COUNTIF('Data R6'!$AB$4:$AB$1001,"<>")+COUNTIF('Data R7'!$AB$4:$AB$1001,"<>")+COUNTIF('Data R4P'!$AB$4:$AB$1001,"<>")+COUNTIF('Data SW'!$AB$4:$AB$1001,"<>") | H21: =IF((COUNTA('Data R1'!$C$4:$C$1001)+COUNTA('Data R2'!$C$4:$C$1001)+COUNTA('Data R3'!$C$4:$C$1001)+COUNTA('Data R4'!$C$4:$C$1001)+COUNTA('Data R5'!$C$4:$C$1001)+COUNTA('Data R6'!$C$4:$C$1001)+COUNTA('Data R7'!$C$4:$C$1001)+COUNTA('Data R4P'!$C$4:$C$1001)+COUNTA('Data SW'!$C$4:$C$1001))=0,0,ROUND((COUNTIF('Data R1'!$AB$4:$AB$1001,"<>")+COUNTIF('Data R2'!$AB$4:$AB$1001,"<>")+COUNTIF('Data R3'!$AB$4:$AB$1001,"<>")+COUNTIF('Data R4'!$AB$4:$AB$1001,"<>")+COUNTIF('Data R5'!$AB$4:$AB$1001,"<>")+COUNTIF('Data R6'!$AB$4:$AB$1001,"<>")+COUNTIF('Data R7'!$AB$4:$AB$1001,"<>")+COUNTIF('Data R4P'!$AB$4:$AB$1001,"<>")+COUNTIF('Data SW'!$AB$4:$AB$1001,"<>"))/(COUNTA('Data R1'!$C$4:$C$1001)+COUNTA('Data R2'!$C$4:$C$1001)+COUNTA('Data R3'!$C$4:$C$1001)+COUNTA('Data R4'!$C$4:$C$1001)+COUNTA('Data R5'!$C$4:$C$1001)+COUNTA('Data R6'!$C$4:$C$1001)+COUNTA('Data R7'!$C$4:$C$1001)+COUNTA('Data R4P'!$C$4:$C$1001)+COUNTA('Data SW'!$C$4:$C$1001))*100,0))
A23: RINGKASAN PER TAHUN (otomatis)
A24: Tahun | B24: Total | C24: Draft Masuk | D24: Dikoreksi | E24: Direvisi | F24: Dicetak | G24: Sudah Dikirim | H24: % Selesai
A25: 2024 | B25: =COUNTIFS('Data R1'!$C$4:$C$1001,"<>",'Data R1'!$AD$4:$AD$1001,$A25)+COUNTIFS('Data R2'!$C$4:$C$1001,"<>",'Data R2'!$AD$4:$AD$1001,$A25)+COUNTIFS('Data R3'!$C$4:$C$1001,"<>",'Data R3'!$AD$4:$AD$1001,$A25)+COUNTIFS('Data R4'!$C$4:$C$1001,"<>",'Data R4'!$AD$4:$AD$1001,$A25)+COUNTIFS('Data R5'!$C$4:$C$1001,"<>",'Data R5'!$AD$4:$AD$1001,$A25)+COUNTIFS('Data R6'!$C$4:$C$1001,"<>",'Data R6'!$AD$4:$AD$1001,$A25)+COUNTIFS('Data R7'!$C$4:$C$1001,"<>",'Data R7'!$AD$4:$AD$1001,$A25)+COUNTIFS('Data R4P'!$C$4:$C$1001,"<>",'Data R4P'!$AD$4:$AD$1001,$A25)+COUNTIFS('Data SW'!$C$4:$C$1001,"<>",'Data SW'!$AD$4:$AD$1001,$A25) | C25: =COUNTIFS('Data R1'!$G$4:$G$1001,"<>",'Data R1'!$AD$4:$AD$1001,$A25)+COUNTIFS('Data R2'!$G$4:$G$1001,"<>",'Data R2'!$AD$4:$AD$1001,$A25)+COUNTIFS('Data R3'!$G$4:$G$1001,"<>",'Data R3'!$AD$4:$AD$1001,$A25)+COUNTIFS('Data R4'!$G$4:$G$1001,"<>",'Data R4'!$AD$4:$AD$1001,$A25)+COUNTIFS('Data R5'!$G$4:$G$1001,"<>",'Data R5'!$AD$4:$AD$1001,$A25)+COUNTIFS('Data R6'!$G$4:$G$1001,"<>",'Data R6'!$AD$4:$AD$1001,$A25)+COUNTIFS('Data R7'!$G$4:$G$1001,"<>",'Data R7'!$AD$4:$AD$1001,$A25)+COUNTIFS('Data R4P'!$G$4:$G$1001,"<>",'Data R4P'!$AD$4:$AD$1001,$A25)+COUNTIFS('Data SW'!$G$4:$G$1001,"<>",'Data SW'!$AD$4:$AD$1001,$A25) | D25: =COUNTIFS('Data R1'!$J$4:$J$1001,"<>",'Data R1'!$AD$4:$AD$1001,$A25)+COUNTIFS('Data R2'!$J$4:$J$1001,"<>",'Data R2'!$AD$4:$AD$1001,$A25)+COUNTIFS('Data R3'!$J$4:$J$1001,"<>",'Data R3'!$AD$4:$AD$1001,$A25)+COUNTIFS('Data R4'!$J$4:$J$1001,"<>",'Data R4'!$AD$4:$AD$1001,$A25)+COUNTIFS('Data R5'!$J$4:$J$1001,"<>",'Data R5'!$AD$4:$AD$1001,$A25)+COUNTIFS('Data R6'!$J$4:$J$1001,"<>",'Data R6'!$AD$4:$AD$1001,$A25)+COUNTIFS('Data R7'!$J$4:$J$1001,"<>",'Data R7'!$AD$4:$AD$1001,$A25)+COUNTIFS('Data R4P'!$J$4:$J$1001,"<>",'Data R4P'!$AD$4:$AD$1001,$A25)+COUNTIFS('Data SW'!$J$4:$J$1001,"<>",'Data SW'!$AD$4:$AD$1001,$A25) | E25: =COUNTIFS('Data R1'!$Z$4:$Z$1001,"<>",'Data R1'!$AD$4:$AD$1001,$A25)+COUNTIFS('Data R2'!$Z$4:$Z$1001,"<>",'Data R2'!$AD$4:$AD$1001,$A25)+COUNTIFS('Data R3'!$Z$4:$Z$1001,"<>",'Data R3'!$AD$4:$AD$1001,$A25)+COUNTIFS('Data R4'!$Z$4:$Z$1001,"<>",'Data R4'!$AD$4:$AD$1001,$A25)+COUNTIFS('Data R5'!$Z$4:$Z$1001,"<>",'Data R5'!$AD$4:$AD$1001,$A25)+COUNTIFS('Data R6'!$Z$4:$Z$1001,"<>",'Data R6'!$AD$4:$AD$1001,$A25)+COUNTIFS('Data R7'!$Z$4:$Z$1001,"<>",'Data R7'!$AD$4:$AD$1001,$A25)+COUNTIFS('Data R4P'!$Z$4:$Z$1001,"<>",'Data R4P'!$AD$4:$AD$1001,$A25)+COUNTIFS('Data SW'!$Z$4:$Z$1001,"<>",'Data SW'!$AD$4:$AD$1001,$A25) | F25: =COUNTIFS('Data R1'!$AA$4:$AA$1001,"<>",'Data R1'!$AD$4:$AD$1001,$A25)+COUNTIFS('Data R2'!$AA$4:$AA$1001,"<>",'Data R2'!$AD$4:$AD$1001,$A25)+COUNTIFS('Data R3'!$AA$4:$AA$1001,"<>",'Data R3'!$AD$4:$AD$1001,$A25)+COUNTIFS('Data R4'!$AA$4:$AA$1001,"<>",'Data R4'!$AD$4:$AD$1001,$A25)+COUNTIFS('Data R5'!$AA$4:$AA$1001,"<>",'Data R5'!$AD$4:$AD$1001,$A25)+COUNTIFS('Data R6'!$AA$4:$AA$1001,"<>",'Data R6'!$AD$4:$AD$1001,$A25)+COUNTIFS('Data R7'!$AA$4:$AA$1001,"<>",'Data R7'!$AD$4:$AD$1001,$A25)+COUNTIFS('Data R4P'!$AA$4:$AA$1001,"<>",'Data R4P'!$AD$4:$AD$1001,$A25)+COUNTIFS('Data SW'!$AA$4:$AA$1001,"<>",'Data SW'!$AD$4:$AD$1001,$A25) | G25: =COUNTIFS('Data R1'!$AB$4:$AB$1001,"<>",'Data R1'!$AD$4:$AD$1001,$A25)+COUNTIFS('Data R2'!$AB$4:$AB$1001,"<>",'Data R2'!$AD$4:$AD$1001,$A25)+COUNTIFS('Data R3'!$AB$4:$AB$1001,"<>",'Data R3'!$AD$4:$AD$1001,$A25)+COUNTIFS('Data R4'!$AB$4:$AB$1001,"<>",'Data R4'!$AD$4:$AD$1001,$A25)+COUNTIFS('Data R5'!$AB$4:$AB$1001,"<>",'Data R5'!$AD$4:$AD$1001,$A25)+COUNTIFS('Data R6'!$AB$4:$AB$1001,"<>",'Data R6'!$AD$4:$AD$1001,$A25)+COUNTIFS('Data R7'!$AB$4:$AB$1001,"<>",'Data R7'!$AD$4:$AD$1001,$A25)+COUNTIFS('Data R4P'!$AB$4:$AB$1001,"<>",'Data R4P'!$AD$4:$AD$1001,$A25)+COUNTIFS('Data SW'!$AB$4:$AB$1001,"<>",'Data SW'!$AD$4:$AD$1001,$A25) | H25: =IF(B25=0,0,ROUND(G25/B25*100,0))
